Workbook

Sheet Register 2025-26
B5: OPERATIONAL RISK REGISTER 2025/26
A9: Link to Outcome | B9: Risk number | C9: Unit | D9: Risk Category | E9: Risk Description | F9: Risk Causes | G9: Consequences | H9: Impact Value (1-5) | I9: Likelihood Value (1-5) | J9: Inherent Risk Value | K9: Current controls | L9: Control Effectiveness | M9: Effectiveness rating | N9: Residual Risk Value | O9: Risk Appetite | P9: Risk Tolerance | Q9: Suggested Risk Response | R9: Risk Owner | S9: Action to improve management of the risk | T9: Action owner | U9: Timeline
A10: Enhanced governance for service delivery efficiency | B10: CS-1 | C10: Corporate Services | D10: Compliance / Regulatory | E10: Inadequate management of performance by supervisors | F10: Non-compliance with EPMDS policy Misalignment of Performance agreements to the Annual Performance Plan and Operational plan | G10: Late submission of PMDS documents Delays in the awarding of performance incentives Negative impact on expenditure projections Negative Audit report Inability to identify performance gaps timeously | H10: 4 | I10: 4 | J10: =H10*I10 -> 16 | K10: EPMDS policy EPMDS appeals committee EPMDS implementation plan Circulars on EPMDS Monitoring of PMDS documents on PERSAL EPMDS Templates EPMDS quality control checklist | L10: satisfactory | M10: =IF(L10="very good", 0.2, IF(L10="good", 0.4, IF(L10="Satisfactory", 0.6, IF(L10="weak", 0.8, IF(L10="non existent", 1))))) -> 0.6 | N10: =J10*M10 -> 9.6 | O10: =IF(N10<=4,"Acceptable ",IF(N10<=14,"Moderalety Acceptable","Unacceptable")) -> Moderalety Acceptable | P10: =IF(N10<=4,"Low Risk",IF(N10<=14,"Medium Risk","High Risk")) -> Medium Risk | Q10: =IF(P10="High Risk","Treatment",IF(P10="Medium Risk","Treatment","Tolerate")) -> Treatment | R10: Chief Director-Corporate Services | S10: Continuous implementation of EPMDS quality control checklist | T10: Director HRD &OD | U10: bi-annually
A11: Enhanced governance for service delivery efficiency | B11: CS-2 | C11: Corporate Services | D11: Compliance / Regulatory | E11: Incorrect record of Leave accruals | F11: Delays in submission of leave forms by management | G11: Overstating of AFS Negative audit opinion | H11: 4 | I11: 4 | J11: =H11*I11 -> 16 | K11: Leave management policy Triplicate leave form Attendance register Leave management tool Persal leave report | L11: very good | M11: =IF(L11="very good", 0.2, IF(L11="good", 0.4, IF(L11="Satisfactory", 0.6, IF(L11="weak", 0.8, IF(L11="non existent", 1))))) -> 0.2 | N11: =J11*M11 -> 3.2 | O11: =IF(N11<=4,"Acceptable ",IF(N11<=14,"Moderalety Acceptable","Unacceptable")) -> Acceptable | P11: =IF(N11<=4,"Low Risk",IF(N11<=14,"Medium Risk","High Risk")) -> Low Risk | Q11: =IF(P11="High Risk","Treatment",IF(P11="Medium Risk","Treatment","Tolerate")) -> Tolerate | R11: Chief Director: Corporate services | S11: Continue to monitor existing controls | T11: Director HRM | U11: Quarterly
A12: Enhanced governance for service delivery efficiency | B12: CS-3 | C12: Corporate Services | D12: Compliance / Regulatory | E12: Default Judgements | F12: The department does not serve and file a notice of intention to defend/oppose The department does not serve and file a notice of intention to defend/oppose/ timeously. The department fails to file a plea/opposing affidavit on a matter. The department enters a defective entry of intention to defend/oppose. | G12: High Legal Fees Fruitless and wasteful expenditure Negative audit outcome | H12: 4 | I12: 2 | J12: =H12*I12 -> 8 | K12: Circular issued to All Staff on the process for handling legal matters Circular on default judgement processes Circular on handling Legal Documents Litigation Policy Court Rules (Higher and Lower Courts) | L12: good | M12: =IF(L12="very good", 0.2, IF(L12="good", 0.4, IF(L12="Satisfactory", 0.6, IF(L12="weak", 0.8, IF(L12="non existent", 1))))) -> 0.4 | N12: =J12*M12 -> 3.2 | O12: =IF(N12<=4,"Acceptable ",IF(N12<=14,"Moderalety Acceptable","Unacceptable")) -> Acceptable | P12: =IF(N12<=4,"Low Risk",IF(N12<=14,"Medium Risk","High Risk")) -> Low Risk | Q12: =IF(P12="High Risk","Treatment",IF(P12="Medium Risk","Treatment","Tolerate")) -> Tolerate | R12: Director: Legal services | S12: Continue to monitor existing controls | U12: Quarterly
A13: Enhanced governance for service delivery efficiency | B13: ICT-01 | C13: Corporate Services | D13: Knowledge and Information Management | E13: Inadequate management of Departmental records and knowledge | F13: Ineffective utilisation of centralised registry services Non utilisation of the authorised departmental file plan Limited storage space for records keeping Inadequate records management capacity (Human Resources) in the department. e.g. Records Manager is not in the Organogram. Misaligned ICT Structure. Lack of knowledge management practices Non compliance with National and Provincial Archives Act | G13: Loss of Departmental information and knowledge Negative audit opinion Data breach Non preservation of institutional memory | H13: 5 | I13: 5 | J13: =H13*I13 -> 25 | K13: National Archives Act Records Management Policy Departmental file plan Procedure Manual Provincial Innovation & Knowledge Management Strategy . Innovation & Knowledge Managements champions appointed. Knowledge Hub (Departmental Website) National Human Settlements knowledge management strategy Succession Plan (HR) Physical records verification form ICT Digital Strategy, Information Systems Security (ISS) Strategy and Plan in place. Provincial Archives policy Secure offsite storage | L13: satisfactory | M13: =IF(L13="very good", 0.2, IF(L13="good", 0.4, IF(L13="Satisfactory", 0.6, IF(L13="weak", 0.8, IF(L13="non existent", 1))))) -> 0.6 | N13: =J13*M13 -> 15 | O13: =IF(N13<=4,"Acceptable ",IF(N13<=14,"Moderalety Acceptable","Unacceptable")) -> Unacceptable | P13: =IF(N13<=4,"Low Risk",IF(N13<=14,"Medium Risk","High Risk")) -> High Risk | Q13: =IF(P13="High Risk","Treatment",IF(P13="Medium Risk","Treatment","Tolerate")) -> Treatment | R13: Chief Director: Strategy and Systems | S13: Conduct awarenesses on records management Monitor the implementation of the records management policy Digitise and automate records management | T13: Director:GICTM | U13: Quarterly Quarterly Quarterly
A14: Socially cohesive and economically viable communities with access to basic services, housing, and economic opportunities | B14: HSFP-1 | C14: Human Settlements Facilitation Programme | D14: Service delivery | E14: Illegal occupation and use of houses | F14: Inadequate capacity at municipal level to manage beneficiary administration processes Manipulation of approved beneficiary lists Delays in project implementation Migration of beneficiaries | G14: Service delivery protests Rightful owners not occupying their houses | H14: 4 | I14: 5 | J14: =H14*I14 -> 20 | K14: Housing Subsidy System Housing Code Beneficiary Allocation Policy Beneficiary Allocation Committees Beneficiary correct occupation guidelines | L14: good | M14: =IF(L14="very good", 0.2, IF(L14="good", 0.4, IF(L14="Satisfactory", 0.6, IF(L14="weak", 0.8, IF(L14="non existent", 1))))) -> 0.4 | N14: =J14*M14 -> 8 | O14: =IF(N14<=4,"Acceptable ",IF(N14<=14,"Moderalety Acceptable","Unacceptable")) -> Moderalety Acceptable | P14: =IF(N14<=4,"Low Risk",IF(N14<=14,"Medium Risk","High Risk")) -> Medium Risk | Q14: =IF(P14="High Risk","Treatment",IF(P14="Medium Risk","Treatment","Tolerate")) -> Treatment | R14: Chief Director: Human Settlements Facilitation Programme | S14: Establishment and monitoring of Beneficiary Allocation Committees to ensure fairness in the allocation process and to avoid possible misallocation and wrongful occupation of houses Provide support to Municipalities regarding Beneficiary Administration | T14: Director: Beneficiary Management | U14: Quarterly Quarterly
A15: Socially cohesive and economically viable communities with access to basic services, housing, and economic opportunities | B15: HSFP-2 | C15: Human Settlements Facilitation Programme | D15: Service delivery | E15: Inadequate implementation of facilitation interventions | F15: Limited budget Lack of co-ordination within the department Lack of participation of key stakeholders | G15: Social unrest. Non compliance of consumers with the housing code. Growing trend of beneficiaries selling subsidised houses Limited understanding by beneficiaries of their rights and responsibilities | H15: 4 | I15: 4 | J15: =H15*I15 -> 16 | K15: Housing code . Consumer Education Framework Social Facilitation Strategy | L15: good | M15: =IF(L15="very good", 0.2, IF(L15="good", 0.4, IF(L15="Satisfactory", 0.6, IF(L15="weak", 0.8, IF(L15="non existent", 1))))) -> 0.4 | N15: =J15*M15 -> 6.4 | O15: =IF(N15<=4,"Acceptable ",IF(N15<=14,"Moderalety Acceptable","Unacceptable")) -> Moderalety Acceptable | P15: =IF(N15<=4,"Low Risk",IF(N15<=14,"Medium Risk","High Risk")) -> Medium Risk | Q15: =IF(P15="High Risk","Treatment",IF(P15="Medium Risk","Treatment","Tolerate")) -> Treatment | R15: Chief Director: Human Settlements Facilitation Programme | S15: Implementation of the Social Facilitation Strategy | T15: Director: Social Facilitation and Customer Care | U15: Quarterly
A16: Socially cohesive and economically viable communities with access to basic services, housing, and economic opportunities | B16: HSFP-3 | C16: Human Settlements Facilitation Programme | D16: Compliance / Regulatory | E16: Procurement of 40% MSMEs from the framework agreement may not be achieved. | F16: 1. There is currently no new projects dedicated to the MSMEs in the approved business plan. 2. MSME Framework Agreement could not be finalised due to the end of validity period which lapsed. 3. No Departmental policy that caters and enforce MSME procurement as the preferential procurement act does not adequately cover appointment of MSME but focuses on designated groups. | G16: Possibility of reputational damage since this was mentioned in the MEC's budget speech as one of the key priorities. | H16: 4 | I16: 5 | J16: =H16*I16 -> 20 | K16: Preferential Procurement Act Public Procurement Act | L16: weak | M16: =IF(L16="very good", 0.2, IF(L16="good", 0.4, IF(L16="Satisfactory", 0.6, IF(L16="weak", 0.8, IF(L16="non existent", 1))))) -> 0.8 | N16: =J16*M16 -> 16 | O16: =IF(N16<=4,"Acceptable ",IF(N16<=14,"Moderalety Acceptable","Unacceptable")) -> Unacceptable | P16: =IF(N16<=4,"Low Risk",IF(N16<=14,"Medium Risk","High Risk")) -> High Risk | Q16: =IF(P16="High Risk","Treatment",IF(P16="Medium Risk","Treatment","Tolerate")) -> Treatment | R16: Chief Director: Human Settlements Facilitation Programme | S16: Acquire lists of MSME contractors appointed by the region who are utilizing 40% of the Human Settlements’ Conditional Grant | T16: Director: Emerging Contractor Development | U16: Annually
A17: Socially cohesive and economically viable communities with access to basic services, housing, and economic opportunities | B17: HSFP-4 | C17: Human Settlements Facilitation Programme | D17: Compliance / Regulatory | E17: Inability for the department to provide input on skills development to unemployed youth (apprenticeship and learning ) | F17: Lack of departmental funding stream for artisan development programme. Dependence on external funding. | G17: Inability to provide artisan skills resource base for departmental projects Inability to develop Artisans. | H17: 3 | I17: 3 | J17: =H17*I17 -> 9 | K17: Annual MoU with Construction Education & Training Authority (CETA) CETA funding for eighty (80) learnership opportunities successfully secured | L17: weak | M17: =IF(L17="very good", 0.2, IF(L17="good", 0.4, IF(L17="Satisfactory", 0.6, IF(L17="weak", 0.8, IF(L17="non existent", 1))))) -> 0.8 | N17: =J17*M17 -> 7.2 | O17: =IF(N17<=4,"Acceptable ",IF(N17<=14,"Moderalety Acceptable","Unacceptable")) -> Moderalety Acceptable | P17: =IF(N17<=4,"Low Risk",IF(N17<=14,"Medium Risk","High Risk")) -> Medium Risk | Q17: =IF(P17="High Risk","Treatment",IF(P17="Medium Risk","Treatment","Tolerate")) -> Treatment | R17: Chief Director: Human Settlements Facilitation Programme | S17: Enhance working relationship with the Construction Education Training Authority (CETA) to receive funding permanently for funding the learnership and apprenticeship programmes. Allocation of funding from OPSAP | T17: Director: Emerging Contractor Development | U17: Annually
A18: Socially cohesive and economically viable communities with access to basic services, housing, and economic opportunities | B18: HSFP-5 | C18: Human Settlements Facilitation Programme | D18: Compliance / Regulatory | E18: Appointed contractors may not adequatly report on the number of jobs created | F18: 1. Appointed contractors do not attach and submit compliance documents such as the contracts between the contractor and EPWP participants, copies of the ID, copies of the attendance and payment registers. 2. Non adherence to current controls | G18: 1. Inadequate reports submitted by contractors get rejected by the EPWP Report System. 2. Target not achieved as a result of inadequate reports on the number of jobs created in Departmental projects submitted by appointed contractors. | H18: 4 | I18: 4 | J18: =H18*I18 -> 16 | K18: Full Adherence to EPWP Guidelines ( Attachment of the compliance documents on EPWP monthly reports by appointed contractors Full adherence to and signing off of the EPWP report checklist attached on payment certificate by Regional Directors to the Accounting Officer's directive pay appointed contractors for value created relative to their scope of work unless they submit fully compliant monthly reports) JBBC 5 Contract (MOU) in cooperation with the Department of Employment and Labor (DEL) to access unemployed labor for placement in Departmental projects when the need arises. | L18: satisfactory | M18: =IF(L18="very good", 0.2, IF(L18="good", 0.4, IF(L18="Satisfactory", 0.6, IF(L18="weak", 0.8, IF(L18="non existent", 1))))) -> 0.6 | N18: =J18*M18 -> 9.6 | O18: =IF(N18<=4,"Acceptable ",IF(N18<=14,"Moderalety Acceptable","Unacceptable")) -> Moderalety Acceptable | P18: =IF(N18<=4,"Low Risk",IF(N18<=14,"Medium Risk","High Risk")) -> Medium Risk | Q18: =IF(P18="High Risk","Treatment",IF(P18="Medium Risk","Treatment","Tolerate")) -> Treatment | R18: Chief Director: Human Settlements Facilitation Programme | S18: The Directorate of Emerging Contractors in cooperation with the Project Managers, EPWP Coordinators, Hands On Support and ECDPWI to collect compliant data from the appointed contractors Prepare an EPWP compliance checklist template for sign off by Project Manager, EPWP coordinator and the Regional Director. | T18: Director: Emerging Contractor Development | U18: Quarterly
A19: Socially cohesive and economically viable communities with access to basic services, housing, and economic opportunities | B19: HSFP-6 | C19: Human Settlements Facilitation Programme | D19: Compliance / Regulatory | E19: Procurement of 10% building materials from black industrialists may not be achieved since there is no policy provision and provision in the contracts of the appointed contractors | F19: 1. Lack of internal and external policy and framework supporting the procurement of materials from the black industirialists. 2. The East London Industrial Development Zone (ELDZ) does not have a target nor KPI to measure to support black industrialists in 2025/26 3. Provincial Treasury Instruction note 7 of 2016/17 does not cater for the procurement of building materials from Black Industrialists by contractors appointed. 4. Currently contracts of the appointed contractors do not have a provision for the procurement of building materials from the Black Industrialists by contractors appointed | G19: 1. Procurement of building material suppliers by contractors who are contracted with the department from 10 percent of the black industrialists may not be achieved. 2. This may cause reputational damage for the Departmen since the MEC pronounced in the budget policy speech as one of the priorities | H19: 4 | I19: 5 | J19: =H19*I19 -> 20 | K19: Black Industrialists 2015 Treasury Instruction Note 7; 2016/17 | L19: weak | M19: =IF(L19="very good", 0.2, IF(L19="good", 0.4, IF(L19="Satisfactory", 0.6, IF(L19="weak", 0.8, IF(L19="non existent", 1))))) -> 0.8 | N19: =J19*M19 -> 16 | O19: =IF(N19<=4,"Acceptable ",IF(N19<=14,"Moderalety Acceptable","Unacceptable")) -> Unacceptable | P19: =IF(N19<=4,"Low Risk",IF(N19<=14,"Medium Risk","High Risk")) -> High Risk | Q19: =IF(P19="High Risk","Treatment",IF(P19="Medium Risk","Treatment","Tolerate")) -> Treatment | R19: Chief Director: Human Settlements Facilitation Programme | S19: 1. Conduct a survey amongst the contractors appointed in all Departmental Regions to determine percentage of Black Industrialists whose building materials is being procured by appointed contractors. 2. Report on percentage of Black Industrialists whose building materials is procured by the contractors appointed 3. Recommend mechanisms for policy Implementation mechanism. | T19: Director: Emerging Contractor Development | U19: Annually
A20: Socially cohesive and economically viable communities with access to basic services, housing, and economic opportunities | B20: HSFP-7 | C20: Human Settlements Facilitation Programme | D20: Service delivery | E20: Delays in the processes of project approval | F20: Departmental Competing Priorities | G20: Lack of service delivery Underperformance by the department (financial and non financial) | H20: 3 | I20: 3 | J20: =H20*I20 -> 9 | K20: Housing Code Housing Policies Continuous implementation of Guideline for the project approval process. | L20: good | M20: =IF(L20="very good", 0.2, IF(L20="good", 0.4, IF(L20="Satisfactory", 0.6, IF(L20="weak", 0.8, IF(L20="non existent", 1))))) -> 0.4 | N20: =J20*M20 -> 3.6 | O20: =IF(N20<=4,"Acceptable ",IF(N20<=14,"Moderalety Acceptable","Unacceptable")) -> Acceptable | P20: =IF(N20<=4,"Low Risk",IF(N20<=14,"Medium Risk","High Risk")) -> Low Risk | Q20: =IF(P20="High Risk","Treatment",IF(P20="Medium Risk","Treatment","Tolerate")) -> Tolerate | R20: Chief Director: Human Settlements Facilitation Programme | S20: Continue to monitor existing controls | T20: Director: Beneficiary Management | U20: Quarterly
A21: Socially cohesive and economically viable communities with access to basic services, housing, and economic opportunities | B21: HSIP 1 | C21: Human Settlements Incremental Programs | D21: Third party performance | E21: Inadequate provision of temporary relief to emergency housing cases | F21: Inability of municipalities to perform the emergency housing assistance function Inadequate capacity of contractors to supply temporal shelters Limited budget against demand Unclear value chain process | G21: Violation of Human rights Exposure of people to vulnerability | H21: 4 | I21: 5 | J21: =H21*I21 -> 20 | K21: Housing Code Service level agreement with appointed contactors Disaster Management Act Supply Chain Management Policy | L21: good | M21: =IF(L21="very good", 0.2, IF(L21="good", 0.4, IF(L21="Satisfactory", 0.6, IF(L21="weak", 0.8, IF(L21="non existent", 1))))) -> 0.4 | N21: =J21*M21 -> 8 | O21: =IF(N21<=4,"Acceptable ",IF(N21<=14,"Moderalety Acceptable","Unacceptable")) -> Moderalety Acceptable | P21: =IF(N21<=4,"Low Risk",IF(N21<=14,"Medium Risk","High Risk")) -> Medium Risk | Q21: =IF(P21="High Risk","Treatment",IF(P21="Medium Risk","Treatment","Tolerate")) -> Treatment | R21: Chief Director: Human Settlements Incremental Programs | S21: Engage and support relevant stakeholders on policy implementation | T21: Director: Emergency Housing and EPHP | U21: Quarterly
A22: Socially cohesive and economically viable communities with access to basic services, housing, and economic opportunities | B22: HSIP 2 | C22: Human Settlements Incremental Programs | D22: Third party performance | E22: Inconsistence in the implementation of the EPHP programme | F22: Limited understanding of the EPHP policy and its implementation by role-players Lack of capacity by CRO's to implement the programme | G22: Blocked projects Inability to achieve the objectives of the policy | H22: 4 | I22: 5 | J22: =H22*I22 -> 20 | K22: Housing code EPHP provincial guidelines | L22: satisfactory | M22: =IF(L22="very good", 0.2, IF(L22="good", 0.4, IF(L22="Satisfactory", 0.6, IF(L22="weak", 0.8, IF(L22="non existent", 1))))) -> 0.6 | N22: =J22*M22 -> 12 | O22: =IF(N22<=4,"Acceptable ",IF(N22<=14,"Moderalety Acceptable","Unacceptable")) -> Moderalety Acceptable | P22: =IF(N22<=4,"Low Risk",IF(N22<=14,"Medium Risk","High Risk")) -> Medium Risk | Q22: =IF(P22="High Risk","Treatment",IF(P22="Medium Risk","Treatment","Tolerate")) -> Treatment | R22: Chief Director: Human Settlements Incremental Programs | S22: Conduct workshops for appointed CRO's to reinforce the understanding Engage stakeholders to align to the implementation of the EPHP Establishment of the CRO panel for capacity enhancement through SCM processes | T22: Director: Emergency Housing and EPHP | U22: 30/09/2025 30/09/2025 31/03/2026
A23: Socially cohesive and economically viable communities with access to basic services, housing, and economic opportunities | B23: HSIP 3 | C23: Human Settlements Incremental Programs | D23: Service delivery | E23: Inability to upgrade informal settlements to the desired phases 1, 2 & 3 | F23: Lack of bulk infrastructure Poor alignment of the implementing partners to the delivery outputs Challenges in land assembly Lack of enforcement of conditions of contract | G23: Social unrest Failure to achieve tenure security , Health security and community empowerment (Water & Sanitation) Non provision of housing opportunities to qualifying beneficiaries | H23: 4 | I23: 4 | J23: =H23*I23 -> 16 | K23: Housing code National informal settlements upgrading framework (DORA) Province wide upgrading strategy National Department of Human Settlements Upgrading framework | L23: satisfactory | M23: =IF(L23="very good", 0.2, IF(L23="good", 0.4, IF(L23="Satisfactory", 0.6, IF(L23="weak", 0.8, IF(L23="non existent", 1))))) -> 0.6 | N23: =J23*M23 -> 9.6 | O23: =IF(N23<=4,"Acceptable ",IF(N23<=14,"Moderalety Acceptable","Unacceptable")) -> Moderalety Acceptable | P23: =IF(N23<=4,"Low Risk",IF(N23<=14,"Medium Risk","High Risk")) -> Medium Risk | Q23: =IF(P23="High Risk","Treatment",IF(P23="Medium Risk","Treatment","Tolerate")) -> Treatment | R23: Chief Director: Human Settlements Incremental Programs | S23: Review province wide upgrading strategy to align with DORA and the National Human Settlements upgrading framework Strengthen partnerships with delivery stakeholders Enhance social facilitation and awareness Enforcement of contractual terms and conditions | T23: Director: Informal Settlements Upgrading | U23: 30/09/2025 Quarterly Quarterly Quarterly
A24: Improved tenure security and expanded access to affordable housing through innovative funding models and partnerships | B24: HSPA- 01 | C24: Human Settlements Property and Assets | D24: Service delivery | E24: Inadequate devolution of land parcels to municipalities | F24: Municipalities refusing to accept offered land parcels Delays in council resolutions Delays by state attorney in appointing correspondents | G24: Land invasion Social unrest/protests Illegal occupation | H24: 5 | I24: 5 | J24: =H24*I24 -> 25 | K24: Section 14 and 15 of Housing Act 107 of 1997 as amended Housing Code Deeds Registry Act 43 of 1937 State Land disposal Act | L24: satisfactory | M24: =IF(L24="very good", 0.2, IF(L24="good", 0.4, IF(L24="Satisfactory", 0.6, IF(L24="weak", 0.8, IF(L24="non existent", 1))))) -> 0.6 | N24: =J24*M24 -> 15 | O24: =IF(N24<=4,"Acceptable ",IF(N24<=14,"Moderalety Acceptable","Unacceptable")) -> Unacceptable | P24: =IF(N24<=4,"Low Risk",IF(N24<=14,"Medium Risk","High Risk")) -> High Risk | Q24: =IF(P24="High Risk","Treatment",IF(P24="Medium Risk","Treatment","Tolerate")) -> Treatment | R24: Chief Director: Housing Property Management | S24: Engage municipalities to provide council resolutions/regulations and or development plans inline with the land to be devolved Engage state attorney to ensure timeous appointment of correspondents | T24: Director: Land Acquisition and Tenure Services | U24: Quarterly Quarterly
... A47: Enhanced governance for service delivery efficiency | B47: SM-04 | C47: Strategy and Systems | D47: Service delivery | E47: Inconsistent stakeholder participation in integrated Human Settlements delivery | F47: Inconsistent support by external stakeholders in Human Settlements programmes | G47: Non delivery of integrated human settlements mandate | H47: 4 | I47: 4 | J47: =H47*I47 -> 16 | K47: Stakeholder engagement and IGR strategy IGR tracking tool Provincial and municipal IGR structures | L47: satisfactory | M47: =IF(L47="very good", 0.2, IF(L47="good", 0.4, IF(L47="Satisfactory", 0.6, IF(L47="weak", 0.8, IF(L47="non existent", 1))))) -> 0.6 | N47: =J47*M47 -> 9.6 | O47: =IF(N47<=4,"Acceptable ",IF(N47<=14,"Moderalety Acceptable","Unacceptable")) -> Moderalety Acceptable | P47: =IF(N47<=4,"Low Risk",IF(N47<=14,"Medium Risk","High Risk")) -> Medium Risk | Q47: =IF(P47="High Risk","Treatment",IF(P47="Medium Risk","Treatment","Tolerate")) -> Treatment | R47: Chief Director: Strategy and Systems | S47: Implementation of the stakeholder engagement and IGR action plan Co-ordinate MEC (Member of the Executive Council) and MMC (Member of the Municipal Council) engagements | T47: Director: Stakeholder Engagement | U47: Quarterly Quarterly
A48: Signature: __________________
A50: Date: __________________

Sheet Sheet3
A1: Link to Outcome | B1: Risk number | C1: Risk Category | D1: Risk Name | E1: Risk Description | F1: Risk Causes | G1: Consequences | H1: Impact Value (1-5) | I1: Likelihood Value (1-5) | J1: Inherent Risk Value | K1: Current controls | L1: Control Effectiveness | M1: Effectiveness rating | N1: Residual Risk Value | O1: Risk Appetite | P1: Risk Tolerance | Q1: Risk Response Treatment | R1: Risk Owner | S1: Action to improve management of the risk | T1: Action owner | U1: Timeline | V1: Current Status
A2: Good Governance | B2: FR1 | E2: Misrepresentation of facts ….. | F2: Submission of falsified Curriculum Vitae (s) Crafting and certification of fictitious variation orders/difficult terrain Certification of fictitious milestones achievements Submission of fictitious Claims submitted by service provider to deliberate deception the Department . i.e duplicate claims , non existences , claims for the working that is done or uncompleted work Manipulation of beneficiary Lists for shelters .i.e Beneficairy that are not in need of temparary shelters reflecting on the request list Collusion between officials and service provider to submit fraudulent claims i.e .inflated prices | G2: Fruitless and wasteful expenditure No value created Financial Losses Reputational damage to government/ Department Litgation cases | H2: 3 | I2: 3 | J2: =H2*I2 -> 9 | L2: Satisfactory | M2: =IF(L2="very good", 0.2, IF(L2="good", 0.4, IF(L2="Satisfactory", 0.6, IF(L2="weak", 0.8, IF(L2="non existent", 1))))) -> 0.6 | N2: =J2*M2 -> 5.4 | O2: =IF(N2<=4,"Acceptable ",IF(N2<=14,"Moderalety Acceptable","Unacceptable")) -> Moderalety Acceptable | P2: =IF(N2<=4,"Low Risk",IF(N2<=14,"Medium Risk","High Risk")) -> Medium Risk | Q2: =IF(P2="High Risk","Treatment",IF(P2="Medium Risk","Treatment","Tolerate")) -> Treatment
A3: Good Governance | B3: FR2 | E3: Bribery….. | F3: Bribery of Community Liason Officer(s) for employment of cheap labour and foreign employees. Manipulation of Project Steering Committee (PSC) by Councillor(s), Clo(s) and Contractors Prioritisation of un-approved beneficiaries on projects and manipulation of community employee lists Possible manipulation of the Emerging contractors list to benefit towards the 30% subcontractors Employees accepting bribes from contractors for fictitiious variation oders and to fast track payment of claims. | G3: Social unrest Slow progress on site Halted and blocked projects Social unrest Slow progress on site Halted and blocked projects Poor quality of projects Delay in service delivery, blocked and halted projects Poor quality on projects | H3: 3 | I3: 3 | J3: =H3*I3 -> 9 | L3: Satisfactory | M3: =IF(L3="very good", 0.2, IF(L3="good", 0.4, IF(L3="Satisfactory", 0.6, IF(L3="weak", 0.8, IF(L3="non existent", 1))))) -> 0.6 | N3: =J3*M3 -> 5.4 | O3: =IF(N3<=4,"Acceptable ",IF(N3<=14,"Moderalety Acceptable","Unacceptable")) -> Moderalety Acceptable | P3: =IF(N3<=4,"Low Risk",IF(N3<=14,"Medium Risk","High Risk")) -> Medium Risk | Q3: =IF(P3="High Risk","Treatment",IF(P3="Medium Risk","Treatment","Tolerate")) -> Treatment
A4: Good Governance | B4: FR3 | E4: Collusion ….. To gain kickbacks | F4: Collusion between project managers and subcontractors Officials may have opportunity to fast-track other invoices against others for kickbacks (rationalise the act) Substitute materials while billing for higher quality or falsification of pay applications Manipulation of procurement processes to favour specific bidder(s)/supplier(s). | G4: Image of Department is compromised/Dented (Labelling) Poor control system | H4: 3 | I4: 3 | J4: =H4*I4 -> 9 | L4: Satisfactory | M4: =IF(L4="very good", 0.2, IF(L4="good", 0.4, IF(L4="Satisfactory", 0.6, IF(L4="weak", 0.8, IF(L4="non existent", 1))))) -> 0.6 | N4: =J4*M4 -> 5.4 | O4: =IF(N4<=4,"Acceptable ",IF(N4<=14,"Moderalety Acceptable","Unacceptable")) -> Moderalety Acceptable | P4: =IF(N4<=4,"Low Risk",IF(N4<=14,"Medium Risk","High Risk")) -> Medium Risk | Q4: =IF(P4="High Risk","Treatment",IF(P4="Medium Risk","Treatment","Tolerate")) -> Treatment
A5: Good Governance | B5: FR4 | H5: 3 | I5: 3 | J5: =H5*I5 -> 9 | L5: Satisfactory | M5: =IF(L5="very good", 0.2, IF(L5="good", 0.4, IF(L5="Satisfactory", 0.6, IF(L5="weak", 0.8, IF(L5="non existent", 1))))) -> 0.6 | N5: =J5*M5 -> 5.4 | O5: =IF(N5<=4,"Acceptable ",IF(N5<=14,"Moderalety Acceptable","Unacceptable")) -> Moderalety Acceptable | P5: =IF(N5<=4,"Low Risk",IF(N5<=14,"Medium Risk","High Risk")) -> Medium Risk | Q5: =IF(P5="High Risk","Treatment",IF(P5="Medium Risk","Treatment","Tolerate")) -> Treatment
A6: Good Governance | B6: FR5 | H6: 3 | I6: 3 | J6: =H6*I6 -> 9 | L6: Satisfactory | M6: =IF(L6="very good", 0.2, IF(L6="good", 0.4, IF(L6="Satisfactory", 0.6, IF(L6="weak", 0.8, IF(L6="non existent", 1))))) -> 0.6 | N6: =J6*M6 -> 5.4 | O6: =IF(N6<=4,"Acceptable ",IF(N6<=14,"Moderalety Acceptable","Unacceptable")) -> Moderalety Acceptable | P6: =IF(N6<=4,"Low Risk",IF(N6<=14,"Medium Risk","High Risk")) -> Medium Risk | Q6: =IF(P6="High Risk","Treatment",IF(P6="Medium Risk","Treatment","Tolerate")) -> Treatment
A7: Good Governance | B7: FR6 | H7: 3 | I7: 3 | J7: =H7*I7 -> 9 | L7: Satisfactory | M7: =IF(L7="very good", 0.2, IF(L7="good", 0.4, IF(L7="Satisfactory", 0.6, IF(L7="weak", 0.8, IF(L7="non existent", 1))))) -> 0.6 | N7: =J7*M7 -> 5.4 | O7: =IF(N7<=4,"Acceptable ",IF(N7<=14,"Moderalety Acceptable","Unacceptable")) -> Moderalety Acceptable | P7: =IF(N7<=4,"Low Risk",IF(N7<=14,"Medium Risk","High Risk")) -> Medium Risk | Q7: =IF(P7="High Risk","Treatment",IF(P7="Medium Risk","Treatment","Tolerate")) -> Treatment
A8: Good Governance | B8: FR7 | H8: 3 | I8: 3 | J8: =H8*I8 -> 9 | L8: Satisfactory | M8: =IF(L8="very good", 0.2, IF(L8="good", 0.4, IF(L8="Satisfactory", 0.6, IF(L8="weak", 0.8, IF(L8="non existent", 1))))) -> 0.6 | N8: =J8*M8 -> 5.4 | O8: =IF(N8<=4,"Acceptable ",IF(N8<=14,"Moderalety Acceptable","Unacceptable")) -> Moderalety Acceptable | P8: =IF(N8<=4,"Low Risk",IF(N8<=14,"Medium Risk","High Risk")) -> Medium Risk | Q8: =IF(P8="High Risk","Treatment",IF(P8="Medium Risk","Treatment","Tolerate")) -> Treatment
A9: Good Governance | B9: FR8 | H9: 3 | I9: 3 | J9: =H9*I9 -> 9 | L9: Satisfactory | M9: =IF(L9="very good", 0.2, IF(L9="good", 0.4, IF(L9="Satisfactory", 0.6, IF(L9="weak", 0.8, IF(L9="non existent", 1))))) -> 0.6 | N9: =J9*M9 -> 5.4 | O9: =IF(N9<=4,"Acceptable ",IF(N9<=14,"Moderalety Acceptable","Unacceptable")) -> Moderalety Acceptable | P9: =IF(N9<=4,"Low Risk",IF(N9<=14,"Medium Risk","High Risk")) -> Medium Risk | Q9: =IF(P9="High Risk","Treatment",IF(P9="Medium Risk","Treatment","Tolerate")) -> Treatment
A10: Good Governance | B10: FR9 | H10: 3 | I10: 3 | J10: =H10*I10 -> 9 | L10: Satisfactory | M10: =IF(L10="very good", 0.2, IF(L10="good", 0.4, IF(L10="Satisfactory", 0.6, IF(L10="weak", 0.8, IF(L10="non existent", 1))))) -> 0.6 | N10: =J10*M10 -> 5.4 | O10: =IF(N10<=4,"Acceptable ",IF(N10<=14,"Moderalety Acceptable","Unacceptable")) -> Moderalety Acceptable | P10: =IF(N10<=4,"Low Risk",IF(N10<=14,"Medium Risk","High Risk")) -> Medium Risk | Q10: =IF(P10="High Risk","Treatment",IF(P10="Medium Risk","Treatment","Tolerate")) -> Treatment
A11: Good Governance | B11: FR10 | H11: 3 | I11: 3 | J11: =H11*I11 -> 9 | L11: Satisfactory | M11: =IF(L11="very good", 0.2, IF(L11="good", 0.4, IF(L11="Satisfactory", 0.6, IF(L11="weak", 0.8, IF(L11="non existent", 1))))) -> 0.6 | N11: =J11*M11 -> 5.4 | O11: =IF(N11<=4,"Acceptable ",IF(N11<=14,"Moderalety Acceptable","Unacceptable")) -> Moderalety Acceptable | P11: =IF(N11<=4,"Low Risk",IF(N11<=14,"Medium Risk","High Risk")) -> Medium Risk | Q11: =IF(P11="High Risk","Treatment",IF(P11="Medium Risk","Treatment","Tolerate")) -> Treatment
B12: FR11 | H12: 3 | I12: 3 | J12: =H12*I12 -> 9 | L12: Satisfactory | M12: =IF(L12="very good", 0.2, IF(L12="good", 0.4, IF(L12="Satisfactory", 0.6, IF(L12="weak", 0.8, IF(L12="non existent", 1))))) -> 0.6 | N12: =J12*M12 -> 5.4 | O12: =IF(N12<=4,"Acceptable ",IF(N12<=14,"Moderalety Acceptable","Unacceptable")) -> Moderalety Acceptable | P12: =IF(N12<=4,"Low Risk",IF(N12<=14,"Medium Risk","High Risk")) -> Medium Risk | Q12: =IF(P12="High Risk","Treatment",IF(P12="Medium Risk","Treatment","Tolerate")) -> Treatment
B13: FR12 | H13: 3 | I13: 3 | J13: =H13*I13 -> 9 | L13: Satisfactory | M13: =IF(L13="very good", 0.2, IF(L13="good", 0.4, IF(L13="Satisfactory", 0.6, IF(L13="weak", 0.8, IF(L13="non existent", 1))))) -> 0.6 | N13: =J13*M13 -> 5.4 | O13: =IF(N13<=4,"Acceptable ",IF(N13<=14,"Moderalety Acceptable","Unacceptable")) -> Moderalety Acceptable | P13: =IF(N13<=4,"Low Risk",IF(N13<=14,"Medium Risk","High Risk")) -> Medium Risk | Q13: =IF(P13="High Risk","Treatment",IF(P13="Medium Risk","Treatment","Tolerate")) -> Treatment
B14: FR13 | H14: 3 | I14: 3 | J14: =H14*I14 -> 9 | L14: Satisfactory | M14: =IF(L14="very good", 0.2, IF(L14="good", 0.4, IF(L14="Satisfactory", 0.6, IF(L14="weak", 0.8, IF(L14="non existent", 1))))) -> 0.6 | N14: =J14*M14 -> 5.4 | O14: =IF(N14<=4,"Acceptable ",IF(N14<=14,"Moderalety Acceptable","Unacceptable")) -> Moderalety Acceptable | P14: =IF(N14<=4,"Low Risk",IF(N14<=14,"Medium Risk","High Risk")) -> Medium Risk | Q14: =IF(P14="High Risk","Treatment",IF(P14="Medium Risk","Treatment","Tolerate")) -> Treatment
B15: FR14 | H15: 3 | I15: 3 | J15: =H15*I15 -> 9 | L15: Satisfactory | M15: =IF(L15="very good", 0.2, IF(L15="good", 0.4, IF(L15="Satisfactory", 0.6, IF(L15="weak", 0.8, IF(L15="non existent", 1))))) -> 0.6 | N15: =J15*M15 -> 5.4 | O15: =IF(N15<=4,"Acceptable ",IF(N15<=14,"Moderalety Acceptable","Unacceptable")) -> Moderalety Acceptable | P15: =IF(N15<=4,"Low Risk",IF(N15<=14,"Medium Risk","High Risk")) -> Medium Risk | Q15: =IF(P15="High Risk","Treatment",IF(P15="Medium Risk","Treatment","Tolerate")) -> Treatment
B16: FR15 | H16: 3 | I16: 3 | J16: =H16*I16 -> 9 | L16: Satisfactory | M16: =IF(L16="very good", 0.2, IF(L16="good", 0.4, IF(L16="Satisfactory", 0.6, IF(L16="weak", 0.8, IF(L16="non existent", 1))))) -> 0.6 | N16: =J16*M16 -> 5.4 | O16: =IF(N16<=4,"Acceptable ",IF(N16<=14,"Moderalety Acceptable","Unacceptable")) -> Moderalety Acceptable | P16: =IF(N16<=4,"Low Risk",IF(N16<=14,"Medium Risk","High Risk")) -> Medium Risk | Q16: =IF(P16="High Risk","Treatment",IF(P16="Medium Risk","Treatment","Tolerate")) -> Treatment
B17: FR16 | H17: 3 | I17: 3 | J17: =H17*I17 -> 9 | L17: Satisfactory | M17: =IF(L17="very good", 0.2, IF(L17="good", 0.4, IF(L17="Satisfactory", 0.6, IF(L17="weak", 0.8, IF(L17="non existent", 1))))) -> 0.6 | N17: =J17*M17 -> 5.4 | O17: =IF(N17<=4,"Acceptable ",IF(N17<=14,"Moderalety Acceptable","Unacceptable")) -> Moderalety Acceptable | P17: =IF(N17<=4,"Low Risk",IF(N17<=14,"Medium Risk","High Risk")) -> Medium Risk | Q17: =IF(P17="High Risk","Treatment",IF(P17="Medium Risk","Treatment","Tolerate")) -> Treatment
B18: FR17 | H18: 3 | I18: 3 | J18: =H18*I18 -> 9 | L18: Satisfactory | M18: =IF(L18="very good", 0.2, IF(L18="good", 0.4, IF(L18="Satisfactory", 0.6, IF(L18="weak", 0.8, IF(L18="non existent", 1))))) -> 0.6 | N18: =J18*M18 -> 5.4 | O18: =IF(N18<=4,"Acceptable ",IF(N18<=14,"Moderalety Acceptable","Unacceptable")) -> Moderalety Acceptable | P18: =IF(N18<=4,"Low Risk",IF(N18<=14,"Medium Risk","High Risk")) -> Medium Risk | Q18: =IF(P18="High Risk","Treatment",IF(P18="Medium Risk","Treatment","Tolerate")) -> Treatment
B19: FR18 | H19: 3 | I19: 3 | J19: =H19*I19 -> 9 | L19: Satisfactory | M19: =IF(L19="very good", 0.2, IF(L19="good", 0.4, IF(L19="Satisfactory", 0.6, IF(L19="weak", 0.8, IF(L19="non existent", 1))))) -> 0.6 | N19: =J19*M19 -> 5.4 | O19: =IF(N19<=4,"Acceptable ",IF(N19<=14,"Moderalety Acceptable","Unacceptable")) -> Moderalety Acceptable | P19: =IF(N19<=4,"Low Risk",IF(N19<=14,"Medium Risk","High Risk")) -> Medium Risk | Q19: =IF(P19="High Risk","Treatment",IF(P19="Medium Risk","Treatment","Tolerate")) -> Treatment
B20: FR19 | H20: 3 | I20: 3 | J20: =H20*I20 -> 9 | L20: Satisfactory | M20: =IF(L20="very good", 0.2, IF(L20="good", 0.4, IF(L20="Satisfactory", 0.6, IF(L20="weak", 0.8, IF(L20="non existent", 1))))) -> 0.6 | N20: =J20*M20 -> 5.4 | O20: =IF(N20<=4,"Acceptable ",IF(N20<=14,"Moderalety Acceptable","Unacceptable")) -> Moderalety Acceptable | P20: =IF(N20<=4,"Low Risk",IF(N20<=14,"Medium Risk","High Risk")) -> Medium Risk | Q20: =IF(P20="High Risk","Treatment",IF(P20="Medium Risk","Treatment","Tolerate")) -> Treatment
B21: FR20 | H21: 3 | I21: 3 | J21: =H21*I21 -> 9 | L21: Satisfactory | M21: =IF(L21="very good", 0.2, IF(L21="good", 0.4, IF(L21="Satisfactory", 0.6, IF(L21="weak", 0.8, IF(L21="non existent", 1))))) -> 0.6 | N21: =J21*M21 -> 5.4 | O21: =IF(N21<=4,"Acceptable ",IF(N21<=14,"Moderalety Acceptable","Unacceptable")) -> Moderalety Acceptable | P21: =IF(N21<=4,"Low Risk",IF(N21<=14,"Medium Risk","High Risk")) -> Medium Risk | Q21: =IF(P21="High Risk","Treatment",IF(P21="Medium Risk","Treatment","Tolerate")) -> Treatment
B22: FR21 | H22: 3 | I22: 3 | J22: =H22*I22 -> 9 | L22: Satisfactory | M22: =IF(L22="very good", 0.2, IF(L22="good", 0.4, IF(L22="Satisfactory", 0.6, IF(L22="weak", 0.8, IF(L22="non existent", 1))))) -> 0.6 | N22: =J22*M22 -> 5.4 | O22: =IF(N22<=4,"Acceptable ",IF(N22<=14,"Moderalety Acceptable","Unacceptable")) -> Moderalety Acceptable | P22: =IF(N22<=4,"Low Risk",IF(N22<=14,"Medium Risk","High Risk")) -> Medium Risk | Q22: =IF(P22="High Risk","Treatment",IF(P22="Medium Risk","Treatment","Tolerate")) -> Treatment
B23: FR22 | H23: 3 | I23: 3 | J23: =H23*I23 -> 9 | L23: Satisfactory | M23: =IF(L23="very good", 0.2, IF(L23="good", 0.4, IF(L23="Satisfactory", 0.6, IF(L23="weak", 0.8, IF(L23="non existent", 1))))) -> 0.6 | N23: =J23*M23 -> 5.4 | O23: =IF(N23<=4,"Acceptable ",IF(N23<=14,"Moderalety Acceptable","Unacceptable")) -> Moderalety Acceptable | P23: =IF(N23<=4,"Low Risk",IF(N23<=14,"Medium Risk","High Risk")) -> Medium Risk | Q23: =IF(P23="High Risk","Treatment",IF(P23="Medium Risk","Treatment","Tolerate")) -> Treatment
... B36: FR35 | H36: 3 | I36: 3 | J36: =H36*I36 -> 9 | L36: Satisfactory | M36: =IF(L36="very good", 0.2, IF(L36="good", 0.4, IF(L36="Satisfactory", 0.6, IF(L36="weak", 0.8, IF(L36="non existent", 1))))) -> 0.6 | N36: =J36*M36 -> 5.4 | O36: =IF(N36<=4,"Acceptable ",IF(N36<=14,"Moderalety Acceptable","Unacceptable")) -> Moderalety Acceptable | P36: =IF(N36<=4,"Low Risk",IF(N36<=14,"Medium Risk","High Risk")) -> Medium Risk | Q36: =IF(P36="High Risk","Treatment",IF(P36="Medium Risk","Treatment","Tolerate")) -> Treatment
H37: 3 | I37: 3 | J37: =H37*I37 -> 9 | L37: Satisfactory | M37: =IF(L37="very good", 0.2, IF(L37="good", 0.4, IF(L37="Satisfactory", 0.6, IF(L37="weak", 0.8, IF(L37="non existent", 1))))) -> 0.6 | N37: =J37*M37 -> 5.4 | O37: =IF(N37<=4,"Acceptable ",IF(N37<=14,"Moderalety Acceptable","Unacceptable")) -> Moderalety Acceptable | P37: =IF(N37<=4,"Low Risk",IF(N37<=14,"Medium Risk","High Risk")) -> Medium Risk | Q37: =IF(P37="High Risk","Treatment",IF(P37="Medium Risk","Treatment","Tolerate")) -> Treatment
H38: 3 | I38: 3 | J38: =H38*I38 -> 9 | L38: Satisfactory | M38: =IF(L38="very good", 0.2, IF(L38="good", 0.4, IF(L38="Satisfactory", 0.6, IF(L38="weak", 0.8, IF(L38="non existent", 1))))) -> 0.6 | N38: =J38*M38 -> 5.4 | O38: =IF(N38<=4,"Acceptable ",IF(N38<=14,"Moderalety Acceptable","Unacceptable")) -> Moderalety Acceptable | P38: =IF(N38<=4,"Low Risk",IF(N38<=14,"Medium Risk","High Risk")) -> Medium Risk | Q38: =IF(P38="High Risk","Treatment",IF(P38="Medium Risk","Treatment","Tolerate")) -> Treatment
H39: 3 | I39: 3 | J39: =H39*I39 -> 9 | L39: Satisfactory | M39: =IF(L39="very good", 0.2, IF(L39="good", 0.4, IF(L39="Satisfactory", 0.6, IF(L39="weak", 0.8, IF(L39="non existent", 1))))) -> 0.6 | N39: =J39*M39 -> 5.4 | O39: =IF(N39<=4,"Acceptable ",IF(N39<=14,"Moderalety Acceptable","Unacceptable")) -> Moderalety Acceptable | P39: =IF(N39<=4,"Low Risk",IF(N39<=14,"Medium Risk","High Risk")) -> Medium Risk | Q39: =IF(P39="High Risk","Treatment",IF(P39="Medium Risk","Treatment","Tolerate")) -> Treatment
H40: 3 | I40: 3 | J40: =H40*I40 -> 9 | L40: Satisfactory | M40: =IF(L40="very good", 0.2, IF(L40="good", 0.4, IF(L40="Satisfactory", 0.6, IF(L40="weak", 0.8, IF(L40="non existent", 1))))) -> 0.6 | N40: =J40*M40 -> 5.4 | O40: =IF(N40<=4,"Acceptable ",IF(N40<=14,"Moderalety Acceptable","Unacceptable")) -> Moderalety Acceptable | P40: =IF(N40<=4,"Low Risk",IF(N40<=14,"Medium Risk","High Risk")) -> Medium Risk | Q40: =IF(P40="High Risk","Treatment",IF(P40="Medium Risk","Treatment","Tolerate")) -> Treatment
H41: 3 | I41: 3 | J41: =H41*I41 -> 9 | L41: Satisfactory | M41: =IF(L41="very good", 0.2, IF(L41="good", 0.4, IF(L41="Satisfactory", 0.6, IF(L41="weak", 0.8, IF(L41="non existent", 1))))) -> 0.6 | N41: =J41*M41 -> 5.4 | O41: =IF(N41<=4,"Acceptable ",IF(N41<=14,"Moderalety Acceptable","Unacceptable")) -> Moderalety Acceptable | P41: =IF(N41<=4,"Low Risk",IF(N41<=14,"Medium Risk","High Risk")) -> Medium Risk | Q41: =IF(P41="High Risk","Treatment",IF(P41="Medium Risk","Treatment","Tolerate")) -> Treatment
H42: 3 | I42: 3 | J42: =H42*I42 -> 9 | L42: Satisfactory | M42: =IF(L42="very good", 0.2, IF(L42="good", 0.4, IF(L42="Satisfactory", 0.6, IF(L42="weak", 0.8, IF(L42="non existent", 1))))) -> 0.6 | N42: =J42*M42 -> 5.4 | O42: =IF(N42<=4,"Acceptable ",IF(N42<=14,"Moderalety Acceptable","Unacceptable")) -> Moderalety Acceptable | P42: =IF(N42<=4,"Low Risk",IF(N42<=14,"Medium Risk","High Risk")) -> Medium Risk | Q42: =IF(P42="High Risk","Treatment",IF(P42="Medium Risk","Treatment","Tolerate")) -> Treatment
H43: 3 | I43: 3 | J43: =H43*I43 -> 9 | L43: Satisfactory | M43: =IF(L43="very good", 0.2, IF(L43="good", 0.4, IF(L43="Satisfactory", 0.6, IF(L43="weak", 0.8, IF(L43="non existent", 1))))) -> 0.6 | N43: =J43*M43 -> 5.4 | O43: =IF(N43<=4,"Acceptable ",IF(N43<=14,"Moderalety Acceptable","Unacceptable")) -> Moderalety Acceptable | P43: =IF(N43<=4,"Low Risk",IF(N43<=14,"Medium Risk","High Risk")) -> Medium Risk | Q43: =IF(P43="High Risk","Treatment",IF(P43="Medium Risk","Treatment","Tolerate")) -> Treatment
H44: 3 | I44: 3 | J44: =H44*I44 -> 9 | L44: Satisfactory | M44: =IF(L44="very good", 0.2, IF(L44="good", 0.4, IF(L44="Satisfactory", 0.6, IF(L44="weak", 0.8, IF(L44="non existent", 1))))) -> 0.6 | N44: =J44*M44 -> 5.4 | O44: =IF(N44<=4,"Acceptable ",IF(N44<=14,"Moderalety Acceptable","Unacceptable")) -> Moderalety Acceptable | P44: =IF(N44<=4,"Low Risk",IF(N44<=14,"Medium Risk","High Risk")) -> Medium Risk | Q44: =IF(P44="High Risk","Treatment",IF(P44="Medium Risk","Treatment","Tolerate")) -> Treatment
H45: 3 | I45: 3 | J45: =H45*I45 -> 9 | L45: Satisfactory | M45: =IF(L45="very good", 0.2, IF(L45="good", 0.4, IF(L45="Satisfactory", 0.6, IF(L45="weak", 0.8, IF(L45="non existent", 1))))) -> 0.6 | N45: =J45*M45 -> 5.4 | O45: =IF(N45<=4,"Acceptable ",IF(N45<=14,"Moderalety Acceptable","Unacceptable")) -> Moderalety Acceptable | P45: =IF(N45<=4,"Low Risk",IF(N45<=14,"Medium Risk","High Risk")) -> Medium Risk | Q45: =IF(P45="High Risk","Treatment",IF(P45="Medium Risk","Treatment","Tolerate")) -> Treatment
H46: 3 | I46: 3 | J46: =H46*I46 -> 9 | L46: Satisfactory | M46: =IF(L46="very good", 0.2, IF(L46="good", 0.4, IF(L46="Satisfactory", 0.6, IF(L46="weak", 0.8, IF(L46="non existent", 1))))) -> 0.6 | N46: =J46*M46 -> 5.4 | O46: =IF(N46<=4,"Acceptable ",IF(N46<=14,"Moderalety Acceptable","Unacceptable")) -> Moderalety Acceptable | P46: =IF(N46<=4,"Low Risk",IF(N46<=14,"Medium Risk","High Risk")) -> Medium Risk | Q46: =IF(P46="High Risk","Treatment",IF(P46="Medium Risk","Treatment","Tolerate")) -> Treatment
H47: 3 | I47: 3 | J47: =H47*I47 -> 9 | L47: Satisfactory | M47: =IF(L47="very good", 0.2, IF(L47="good", 0.4, IF(L47="Satisfactory", 0.6, IF(L47="weak", 0.8, IF(L47="non existent", 1))))) -> 0.6 | N47: =J47*M47 -> 5.4 | O47: =IF(N47<=4,"Acceptable ",IF(N47<=14,"Moderalety Acceptable","Unacceptable")) -> Moderalety Acceptable | P47: =IF(N47<=4,"Low Risk",IF(N47<=14,"Medium Risk","High Risk")) -> Medium Risk | Q47: =IF(P47="High Risk","Treatment",IF(P47="Medium Risk","Treatment","Tolerate")) -> Treatment
H48: 3 | I48: 3 | J48: =H48*I48 -> 9 | L48: Satisfactory | M48: =IF(L48="very good", 0.2, IF(L48="good", 0.4, IF(L48="Satisfactory", 0.6, IF(L48="weak", 0.8, IF(L48="non existent", 1))))) -> 0.6 | N48: =J48*M48 -> 5.4 | O48: =IF(N48<=4,"Acceptable ",IF(N48<=14,"Moderalety Acceptable","Unacceptable")) -> Moderalety Acceptable | P48: =IF(N48<=4,"Low Risk",IF(N48<=14,"Medium Risk","High Risk")) -> Medium Risk | Q48: =IF(P48="High Risk","Treatment",IF(P48="Medium Risk","Treatment","Tolerate")) -> Treatment
... H57: 3 | I57: 3 | J57: =H57*I57 -> 9 | L57: Satisfactory | M57: =IF(L57="very good", 0.2, IF(L57="good", 0.4, IF(L57="Satisfactory", 0.6, IF(L57="weak", 0.8, IF(L57="non existent", 1))))) -> 0.6 | N57: =J57*M57 -> 5.4 | O57: =IF(N57<=4,"Acceptable ",IF(N57<=14,"Moderalety Acceptable","Unacceptable")) -> Moderalety Acceptable | P57: =IF(N57<=4,"Low Risk",IF(N57<=14,"Medium Risk","High Risk")) -> Medium Risk | Q57: =IF(P57="High Risk","Treatment",IF(P57="Medium Risk","Treatment","Tolerate")) -> Treatment

Sheet Monitoring Tool
A1: Chief Directorate | B1: Risk No. | C1: Risk Description | D1: Action to improve management of the risk | E1: Action Owner | F1: Timeline | G1: Current Status | H1: Reasons for deviation & recovery plan | I1: New Timeline | J1: Action in Quarter? | K1: Actions Completed? | L1: Residual Risk Value as at 30 June 2025
A2: CS | B2: CS-1 | C2: Inadequate management of performance by supervisors | D2: Continuous implementation of EPMDS quality control checklist | E2: Director HRD &OD | F2: Quarterly | G2: Quality control check list is part of the submission of PMDS documents. PMDS Unit does not accept documents without the quality control checklist. | H2: None | J2: Yes | K2: Completed
A3: CS | B3: CS-2 | C3: Incorrect record of Leave accruals | D3: The Risk has been tolerated in as far as the Risk Tolerance level, however risk is still managed. | E3: Director HRM | F3: Quarterly | G3: Top Management and SMS members were trained on eleave and currently using the system 15 May 2025. All other employees of the department used the e-leave system from the 01 September 2025. | H3: None | J3: Yes | K3: Completed
A4: CS | B4: CS-3 | C4: Default Judgements | D4: The Risk has been tolerated in as far as the Risk Tolerance level, however risk is still managed. | E4: Director : Legal | F4: Quarterly | G4: Still monitoring the existing controls for the first and second quarter, a new monitoring control will be implemented when the need arise in the third quarter. | J4: Yes | K4: Completed | L4: ='Register 2025-26'!V12 -> 0
A5: CS | B5: ICT-01 | C5: Inadequate management of Departmental records and knowledge | D5: Conduct awarenesses on records management | E5: Director:GICTM | F5: Quarterly | G5: An awareness session was conducted in collaboration with change management unit with the aim of introducing a new departmental records management system (MemoApp). | J5: Yes | K5: Completed
A6: CS | D6: Monitor the implementation of the records management policy | E6: Director:GICTM | F6: Quarterly | G6: All staff members were onboarded into a Mema-App system and some of the directorates' file plan has been reviewed and configured on the systems. The review of the file plan for other units is still on-going. All users were also training on the use of the systems. | J6: Yes | K6: Completed
A7: CS | D7: Digitise and automate records management | E7: Director:GICTM | F7: Quarterly | G7: The Memo App has been implemented to automate records management processes within the department. The implementation of this system will streamline records-keeping, improve efficiency and ensure that all departmental records are managed effectively. | J7: Yes | K7: Completed
A8: HSFP | B8: HSFP-1 | C8: Illegal occupation and use of houses | D8: Establishment and monitoring of Beneficiary Allocation Committees to ensure fairness in the allocation process and to avoid possible misallocation and wrongful occupation of houses | E8: Director: Beneficiary Management | F8: Quarterly | G8: BAC were established in the following municipalities: - Resuscitation of BAC in Sundays River LM, Beneficiary Correct Occupation (BCO) was done in the following Municipality: - Elundini Local Municipality phase 2 of the Ugie project. - Tracing of Missing Beneficiaries in Matatiele Local Municipality | J8: Yes | K8: Completed | L8: ='Register 2025-26'!V14 -> 0
A9: HSFP | D9: Provide support to Municipalities regarding Beneficiary Administration | E9: Director: Beneficiary Management | F9: Quarterly | G9: Beneficiary Allocation policy was conducted with Capacity Building in the following municipalities: - Ndlambe Local Municipality. | J9: Yes | K9: Completed
A10: HSFP | B10: HSFP-2 | C10: Inadequate implementation of facilitation interventions | D10: Implementation of the Social Facilitation Strategy | E10: Director: Social Facilitation and Customer Care | F10: Quarterly | G10: Social facilitation strategy has been implemented in various departmental projects during quarter under review where five (5) interventions were implemented to respond on social issues | J10: Yes | K10: Completed | L10: ='Register 2025-26'!V15 -> 0
A11: HSFP | B11: HSFP-3 | C11: Procurement of 40% MSMEs from the framework agreement may not be achieved. | D11: Acquire lists of MSME contractors appointed by the region who are utilizing 40% of the Human Settlements’ Conditional Grant | E11: Director: Emerging Contractor Development | F11: Quarterly | G11: List of MSMEs and the Category B contractors appointed from the Framework Agreement with between one and one hundred (01 - 100) units was acquired from the Directorate of Supply Chain Management and the regions. The list will be utilised to determine percentage of the amount paid to them relative to the Human Settlements Conditional Grant. | J11: Yes | K11: Completed | L11: ='Register 2025-26'!V16 -> 0
A12: HSFP | B12: HSFP-4 | C12: Inability for the department to provide input on skills development to unemployed youth (apprenticeship and learning ) | D12: Enhance working relationship with the Construction Education Training Authority (CETA) to receive funding permanently for funding the learnership and apprenticeship programmes. | E12: Director: Emerging Contractor Development | F12: Annually | G12: CETA funding for eighty (80) learnership opportunities successfully secured | H12: None | J12: No | L12: ='Register 2025-26'!V17 -> 0
A13: HSFP | D13: Allocation of funding from OPSAP | E13: Director: Emerging Contractor Development | F13: Annually | G13: R1.5 million has been approved for allocation from the OPSCAP to carry out the Apprenticeship programme. Through this fund, it is anticipated that the Directorate will be able to procure the training service provider, however, there has been a delay in the processing thereof. | H13: None | J13: No
A14: HSFP | B14: HSFP-5 | C14: Appointed contractors may not adequately report on the number of jobs created | D14: The Directorate of Emerging Contractors in cooperation with the Project Managers, EPWP Coordinators, Hands On Support and ECDPWI to collect compliant data from the appointed contractors | E14: Director: Emerging Contractor Development | F14: Quarterly | G14: Arising from the cooperation with the ECDPWI there has been an improvement in EPWP reporting. This cooperation resulted in the Department exceeding the National Department Public Works & Infrastructure half year target of five hundred by eighty eighty (88). The Department is on track to achieve the provincial target of five thousand eight hundred and thirty four (5 834). | J14: Yes | K14: Completed
A15: HSFP | D15: Prepare an EPWP compliance checklist template for sign off by Project Manager, EPWP coordinator and the Regional Director. | E15: Director: Emerging Contractor Development | F15: Quarterly | G15: EPWP Checklists was prepared and distributed to all Regional Directors. | J15: Yes | K15: Completed
A16: HSFP | D16: Acquire labour for employment in projects when and where required from the Department of Employment and Labour. | E16: Director: Emerging Contractor Development | F16: Quarterly | G16: There has been an agreement with the Department of Labour and Employment to access its database of unemployed personnel for the Departmental projects should the need arise. | J16: Yes | K16: Completed
A17: HSFP | B17: HSFP-6 | C17: Procurement of 10% building materials from black industrialists may not be achieved since there is no policy provision and provision in the contracts of the appointed contractors | D17: Conduct a survey amongst the contractors appointed in all Departmental Regions to determine percentage of Black Industrialists whose building materials is being procured by appointed contractor | E17: Director: Emerging Contractor Development | F17: 31/03/2025 | G17: on the 5th August 2025 the survey questionnaire was emailed to one hundred and thirty eight (138) contractors appointed by the Department to determine if they procure building materials from the Black Industrialists. To date six (06) contractors have responded. The Directorate will continue engaging contractors to cooperate in this regard. | J17: No | L17: ='Register 2025-26'!V19 -> 0
A18: HSFP | D18: Report on percentage of Black Industrialists whose building materials is procured by the contractors appointed | E18: Director: Emerging Contractor Development | F18: 31/03/2025 | G18: The report is dependent on the feedback from contractors relative to the procurement of the building material supplies from the Black Industrialists. | J18: No
A19: HSFP | D19: Recommend mechanisms for policy Implementation mechanism. | E19: Director: Emerging Contractor Development | F19: 31/03/2025 | G19: No recommendation at this stage | J19: No
A20: HSFP | B20: HSFP-7 | C20: Delays in the processes of project approval | D20: The Risk has been tolerated in as far as the Risk Tolerance level, however risk is still managed. | E20: Director: Beneficiary Management | F20: Quarterly | G20: The are no new projects submitted for the quarter. The appointment of the Assessment committees members is underway. The department is dealing with unblocking of blocked projects, the funding adjustments were done through the adhoc process for MEC approval. Currently there are no delays in the process. | J20: Yes | K20: Completed | L20: ='Register 2025-26'!V20 -> 0
A21: HSIP | B21: HSIP 1 | C21: Inadequate provision of temporary relief to emergency housing cases | D21: Engage and support relevant stakeholders on policy implementation | E21: Director: Emergency Housing and EPHP | F21: Quarterly | G21: There were no policy engagements as the accredited Municipalities are independently performing the Emergency Housing function and accessing funding directly from National Department of Human Settlements.Non- accredited Municipalities are able to perform functions associated with the provision of emergency housing programme by the Province. | H21: None | I21: N/A | J21: Yes | K21: Completed | L21: ='Register 2025-26'!V21 -> 0
A22: HSIP | B22: HSIP 2 | C22: Inconsistence in the implementation of the EPHP programme | D22: Conduct workshops for appointed CRO's to reinforce the understanding | E22: Director: Emergency Housing and EPHP | F22: Quarterly | G22: There were no new CRO's appointed hence no workshops conducted | H22: None | I22: N/A | J22: Yes | K22: Completed | L22: ='Register 2025-26'!V22 -> 0
A23: HSIP | D23: Engage stakeholders to align to the implementation of the EPHP | E23: Director: Emergency Housing and EPHP | F23: Quarterly | G23: The current projects under implementation are implemented in line with the policy hence no need for engagement of stakeholders | H23: None | I23: N/A | J23: Yes | K23: Completed
A24: HSIP | D24: Establishment of the CRO panel for capacity enhancement through SCM processes | E24: Director: Emergency Housing and EPHP | F24: 31/03/2026 | G24: Draft Terms of Reference in place | H24: None | I24: Fourth quarter | J24: No
A25: HSIP | B25: HSIP 3 | C25: Inability to upgrade informal settlements to the desired phases 1, 2 & 3 | D25: Review province wide upgrading strategy to align with DORA and the National Human Settlements upgrading framework | E25: Director: Informal Settlements Upgrading | F25: 30/09/2025 | G25: The department is reviewing the strategy for the MTDP following the reduction of the funding from National | H25: The department is awaiting clarity on outer years funding | I25: Next Quarter | J25: Yes | K25: Not Completed | L25: ='Register 2025-26'!V23 -> 0
A26: HSIP | D26: Strengthen partnerships with delivery stakeholders | E26: Director: Informal Settlements Upgrading | F26: Quarterly | G26: The internal partnerships have been strengthened with Land Acquisition, Social Facilitation and Regions. | H26: None | I26: N/A | J26: Yes | K26: Completed
A27: HSIP | D27: Enhance social facilitation and awareness | E27: Director: Informal Settlements Upgrading | F27: Quarterly | G27: The consolidated departmental social facilitation strategy is being implemented through the regional social facilitation to include the UISP. | H27: None | I27: N/A | J27: Yes | K27: Completed
A28: HSIP | D28: Enforcement of contractual terms and conditions | E28: Director: Informal Settlements Upgrading | F28: Quarterly | G28: All contracts have the terms of performance effectively enforced. | H28: None | I28: N/A | J28: Yes | K28: Completed
A29: HSPA | B29: HSPA- 01 | C29: Inadequate devolution of land parcels to municipalities | D29: Engage municipalities to provide council resolutions/regulations and or development plans inline with the land to be devolved | E29: Director: Land Acquisition and Tenure Services | F29: Quarterly | G29: Council resolutions provided | H29: No deviation | J29: Yes | K29: Completed | L29: ='Register 2025-26'!V24 -> 0
A30: HSPA | D30: Engage state attorney to ensure timeous appointment of correspondents | E30: Director: Land Acquisition and Tenure Services | F30: Quarterly | G30: Engagements are being done with the State Attorney | H30: No deviation | J30: Yes | K30: Completed
